2016-09-20 00:03:21.223 [error] <0.189.0> Supervisor 'Elixir.Logger.Supervisor' had child undefined started with 'Elixir.Logger.Watcher':watcher(error_logger, 'Elixir.Logger.ErrorHandler', {true,false,500}, link) at <0.194.0> exit with reason normal in context child_terminated
2016-09-28 20:25:19.440 [error] <0.782.0> Supervisor 'Elixir.Logger.Supervisor' had child undefined started with 'Elixir.Logger.Watcher':watcher(error_logger, 'Elixir.Logger.ErrorHandler', {true,false,500}, link) at <0.787.0> exit with reason normal in context child_terminated
2016-09-28 20:26:59.261 [error] emulator Error in process <0.6109.0> with exit value:
{undef,[{'Elixir.Yams.Handle',open,[<<"94854412-85f4-11e6-9ecb-c485082be198">>],[]},{'Elixir.Perf.Runner',execute,1,[{file,"lib/perf/runner.ex"},{line,35}]}]}
2016-09-28 20:26:59.263 [error] <0.6011.0> gen_server 'Elixir.Perf.Runner.RunServer' terminated with reason: #{'__exception__' => true,'__struct__' => 'Elixir.Ecto.InvalidChangesetError',action => update,changeset => #{'__struct__' => 'Elixir.Ecto.Changeset',action => update,changes => #{finished_at => #{'__struct__' => 'Elixir.Ecto.DateTime',day => 29,hour => 3,min => 26,month => 9,sec => 59,usec => 0,year => 2016},status => #{'__struct__' => 'Elixir.Ecto.Changeset',action => update,changes => #{raw => <<"foo">>,type => <<"failed">>},constraints => [],data => #{'__meta__' => #{'__struct__' => 'Elixir.Ecto.Schema.Metadata',...},...},...}},...}} in 'Elixir.Ecto.Repo.Schema':'update!'/4 line 132
2016-09-28 20:26:59.263 [error] <0.6011.0> CRASH REPORT Process 'Elixir.Perf.Runner.RunServer' with 0 neighbours exited with reason: #{'__exception__' => true,'__struct__' => 'Elixir.Ecto.InvalidChangesetError',action => update,changeset => #{'__struct__' => 'Elixir.Ecto.Changeset',action => update,changes => #{finished_at => #{'__struct__' => 'Elixir.Ecto.DateTime',day => 29,hour => 3,min => 26,month => 9,sec => 59,usec => 0,year => 2016},status => #{'__struct__' => 'Elixir.Ecto.Changeset',action => update,changes => #{raw => <<"foo">>,type => <<"failed">>},constraints => [],data => #{'__meta__' => #{'__struct__' => 'Elixir.Ecto.Schema.Metadata',...},...},...}},...}} in 'Elixir.Ecto.Repo.Schema':'update!'/4 line 132 in gen_server:terminate/7 line 826
2016-09-28 20:26:59.264 [error] <0.1008.0> Supervisor 'Elixir.Perf.Runner' had child undefined started with 'Elixir.Perf.Runner.RunServer':start_link() at <0.6011.0> exit with reason #{'__exception__' => true,'__struct__' => 'Elixir.Ecto.InvalidChangesetError',action => update,changeset => #{'__struct__' => 'Elixir.Ecto.Changeset',action => update,changes => #{finished_at => #{'__struct__' => 'Elixir.Ecto.DateTime',day => 29,hour => 3,min => 26,month => 9,sec => 59,usec => 0,year => 2016},status => #{'__struct__' => 'Elixir.Ecto.Changeset',action => update,changes => #{raw => <<"foo">>,type => <<"failed">>},constraints => [],data => #{'__meta__' => #{'__struct__' => 'Elixir.Ecto.Schema.Metadata',...},...},...}},...}} in 'Elixir.Ecto.Repo.Schema':'update!'/4 line 132 in context child_terminated
2016-09-28 20:26:59.929 [error] <0.6129.0> CRASH REPORT Process <0.6129.0> with 0 neighbours exited with reason: call to undefined function 'Elixir.Yams.Handle':open(<<"94854412-85f4-11e6-9ecb-c485082be198">>) in gen_server:init_it/6 line 352
2016-09-28 20:27:59.856 [error] <0.6217.0> CRASH REPORT Process <0.6217.0> with 0 neighbours exited with reason: no function clause matching 'Elixir.IO':chardata_to_string(nil) line 412 in gen_server:init_it/6 line 352
2016-09-28 20:27:59.900 [error] <0.904.0> Ranch listener 'Elixir.Perf.Endpoint.HTTP' had connection process started with cowboy_protocol:start_link/4 at <0.6204.0> exit with reason: {{#{'__exception__' => true,'__struct__' => 'Elixir.Poison.EncodeError',message => nil,value => <0.6216.0>},[{'Elixir.Poison.Encoder.Any',encode,2,[{file,"lib/poison/encoder.ex"},{line,354}]},{'Elixir.Poison.Encoder.Map','-encode/3-fun-1-',4,[{file,"lib/poison/encoder.ex"},{line,213}]},{'Elixir.Poison.Encoder.Map','-encode/3-lists^foldl/2-0-',3,[{file,"lib/poison/encoder.ex"},{line,214}]},{'Elixir.Poison.Encoder.Map',encode,3,[{file,"lib/poison/encoder.ex"},{line,214}]},{'Elixir.Poison.Encoder.Map','-encode/3-fun-1-',4,[{file,"lib/poison/encoder.ex"},{line,213}]},{'Elixir.Poison.Encoder.Map','-encode/3-lists^foldl/2-0-',3,[{file,"lib/poison/encoder.ex"},{line,214}]},{'Elixir.Poison.Encoder.Map',encode,3,[{file,"lib/poison/encoder.ex"},{line,214}]},{'Elixir.Poison.Encoder.Map','-encode/3-fun-1-',4,[{file,"lib/poison/encoder.ex"},{line,213}]},{'Elixir.Poison.Encoder.Map','-encode/3-lists^foldl/2-0-',3,[{file,"lib/poison/encoder.ex"},{line,214}]},{'Elixir.Poison.Encoder.Map',encode,3,[{file,"lib/poison/encoder.ex"},{line,214}]},{'Elixir.Poison','encode!',2,[{file,"lib/poison.ex"},{line,41}]},{'Elixir.Phoenix.Transports.WebSocketSerializer','encode!',1,[{file,"lib/phoenix/transports/websocket_serializer.ex"},{line,25}]},{'Elixir.Phoenix.Transports.WebSocket',encode_reply,2,[{file,"lib/phoenix/transports/websocket.ex"},{line,171}]},{'Elixir.Phoenix.Endpoint.CowboyWebSocket',websocket_handle,3,[{file,"lib/phoenix/endpoint/cowboy_websocket.ex"},{line,77}]},{cowboy_websocket,handler_call,7,[{file,"src/cowboy_websocket.erl"},{line,588}]},{'Elixir.Phoenix.Endpoint.CowboyWebSocket',resume,3,[{file,"lib/phoenix/endpoint/cowboy_websocket.ex"},{line,49}]},{cowboy_protocol,execute,4,[{file,"src/cowboy_protocol.erl"},{line,442}]}]},{'Elixir.Phoenix.Endpoint.CowboyWebSocket',resume,[]}}
2016-09-28 20:28:02.909 [error] <0.6226.0> CRASH REPORT Process <0.6226.0> with 0 neighbours exited with reason: no function clause matching 'Elixir.IO':chardata_to_string(nil) line 412 in gen_server:init_it/6 line 352
2016-09-28 20:28:02.914 [error] <0.904.0> Ranch listener 'Elixir.Perf.Endpoint.HTTP' had connection process started with cowboy_protocol:start_link/4 at <0.6218.0> exit with reason: {{#{'__exception__' => true,'__struct__' => 'Elixir.Poison.EncodeError',message => nil,value => <0.6225.0>},[{'Elixir.Poison.Encoder.Any',encode,2,[{file,"lib/poison/encoder.ex"},{line,354}]},{'Elixir.Poison.Encoder.Map','-encode/3-fun-1-',4,[{file,"lib/poison/encoder.ex"},{line,213}]},{'Elixir.Poison.Encoder.Map','-encode/3-lists^foldl/2-0-',3,[{file,"lib/poison/encoder.ex"},{line,214}]},{'Elixir.Poison.Encoder.Map',encode,3,[{file,"lib/poison/encoder.ex"},{line,214}]},{'Elixir.Poison.Encoder.Map','-encode/3-fun-1-',4,[{file,"lib/poison/encoder.ex"},{line,213}]},{'Elixir.Poison.Encoder.Map','-encode/3-lists^foldl/2-0-',3,[{file,"lib/poison/encoder.ex"},{line,214}]},{'Elixir.Poison.Encoder.Map',encode,3,[{file,"lib/poison/encoder.ex"},{line,214}]},{'Elixir.Poison.Encoder.Map','-encode/3-fun-1-',4,[{file,"lib/poison/encoder.ex"},{line,213}]},{'Elixir.Poison.Encoder.Map','-encode/3-lists^foldl/2-0-',3,[{file,"lib/poison/encoder.ex"},{line,214}]},{'Elixir.Poison.Encoder.Map',encode,3,[{file,"lib/poison/encoder.ex"},{line,214}]},{'Elixir.Poison','encode!',2,[{file,"lib/poison.ex"},{line,41}]},{'Elixir.Phoenix.Transports.WebSocketSerializer','encode!',1,[{file,"lib/phoenix/transports/websocket_serializer.ex"},{line,25}]},{'Elixir.Phoenix.Transports.WebSocket',encode_reply,2,[{file,"lib/phoenix/transports/websocket.ex"},{line,171}]},{'Elixir.Phoenix.Endpoint.CowboyWebSocket',websocket_handle,3,[{file,"lib/phoenix/endpoint/cowboy_websocket.ex"},{line,77}]},{cowboy_websocket,handler_call,7,[{file,"src/cowboy_websocket.erl"},{line,588}]},{'Elixir.Phoenix.Endpoint.CowboyWebSocket',resume,3,[{file,"lib/phoenix/endpoint/cowboy_websocket.ex"},{line,49}]},{cowboy_protocol,execute,4,[{file,"src/cowboy_protocol.erl"},{line,442}]}]},{'Elixir.Phoenix.Endpoint.CowboyWebSocket',resume,[]}}
2016-09-28 20:28:10.045 [error] <0.194.0> Supervisor 'Elixir.Logger.Supervisor' had child undefined started with 'Elixir.Logger.Watcher':watcher(error_logger, 'Elixir.Logger.ErrorHandler', {true,false,500}, link) at <0.199.0> exit with reason normal in context child_terminated
2016-09-28 20:28:13.555 [error] <0.5455.0> CRASH REPORT Process <0.5455.0> with 0 neighbours exited with reason: no function clause matching 'Elixir.IO':chardata_to_string(nil) line 412 in gen_server:init_it/6 line 352
2016-09-28 20:28:13.608 [error] <0.316.0> Ranch listener 'Elixir.Perf.Endpoint.HTTP' had connection process started with cowboy_protocol:start_link/4 at <0.5443.0> exit with reason: {{#{'__exception__' => true,'__struct__' => 'Elixir.Poison.EncodeError',message => nil,value => <0.5454.0>},[{'Elixir.Poison.Encoder.Any',encode,2,[{file,"lib/poison/encoder.ex"},{line,354}]},{'Elixir.Poison.Encoder.Map','-encode/3-fun-1-',4,[{file,"lib/poison/encoder.ex"},{line,213}]},{'Elixir.Poison.Encoder.Map','-encode/3-lists^foldl/2-0-',3,[{file,"lib/poison/encoder.ex"},{line,214}]},{'Elixir.Poison.Encoder.Map',encode,3,[{file,"lib/poison/encoder.ex"},{line,214}]},{'Elixir.Poison.Encoder.Map','-encode/3-fun-1-',4,[{file,"lib/poison/encoder.ex"},{line,213}]},{'Elixir.Poison.Encoder.Map','-encode/3-lists^foldl/2-0-',3,[{file,"lib/poison/encoder.ex"},{line,214}]},{'Elixir.Poison.Encoder.Map',encode,3,[{file,"lib/poison/encoder.ex"},{line,214}]},{'Elixir.Poison.Encoder.Map','-encode/3-fun-1-',4,[{file,"lib/poison/encoder.ex"},{line,213}]},{'Elixir.Poison.Encoder.Map','-encode/3-lists^foldl/2-0-',3,[{file,"lib/poison/encoder.ex"},{line,214}]},{'Elixir.Poison.Encoder.Map',encode,3,[{file,"lib/poison/encoder.ex"},{line,214}]},{'Elixir.Poison','encode!',2,[{file,"lib/poison.ex"},{line,41}]},{'Elixir.Phoenix.Transports.WebSocketSerializer','encode!',1,[{file,"lib/phoenix/transports/websocket_serializer.ex"},{line,25}]},{'Elixir.Phoenix.Transports.WebSocket',encode_reply,2,[{file,"lib/phoenix/transports/websocket.ex"},{line,171}]},{'Elixir.Phoenix.Endpoint.CowboyWebSocket',websocket_handle,3,[{file,"lib/phoenix/endpoint/cowboy_websocket.ex"},{line,77}]},{cowboy_websocket,handler_call,7,[{file,"src/cowboy_websocket.erl"},{line,588}]},{'Elixir.Phoenix.Endpoint.CowboyWebSocket',resume,3,[{file,"lib/phoenix/endpoint/cowboy_websocket.ex"},{line,49}]},{cowboy_protocol,execute,4,[{file,"src/cowboy_protocol.erl"},{line,442}]}]},{'Elixir.Phoenix.Endpoint.CowboyWebSocket',resume,[]}}
2016-09-28 20:28:20.113 [error] <0.5490.0> CRASH REPORT Process <0.5490.0> with 0 neighbours exited with reason: no function clause matching 'Elixir.IO':chardata_to_string(nil) line 412 in gen_server:init_it/6 line 352
2016-09-28 20:28:20.152 [error] emulator Error in process <0.5489.0> with exit value:
{{badmatch,{error,{badarg,[{erlang,link,[{function_clause,[{'Elixir.IO',chardata_to_string,[nil],[{file,"lib/io.ex"},{line,412}]},{'Elixir.Path',join,2,[{file,"lib/path.ex"},{line,468}]},{'Elixir.Yams.Session',init,1,[{file,"lib/yams/session.ex"},{line,7}]},{gen_server,init_it,6,[{file,"gen_server.erl"},{line,328}]},{proc_lib,init_p_do_apply,3,[{file,"proc_lib.erl"},{line,240}]}]}],[]},{'Elixir.Perf.Runner.Consumer',init,1,[{file,"lib/perf/runner/consumer.ex"},{line,15}]},{'Elixir.Experimental.GenStage',init,1,[{file,"lib/gen_stage.ex"},{line,1213}]},{gen_server,init_it,6,[{file,"gen_server.erl"},{line,328}]},{proc_lib,init_p_do_apply,3,[{file,"proc_lib.erl"},{line,240}]}]}}},[{'Elixir.Perf.Runner',execute,1,[{file,"lib/perf/runner.ex"},{line,37}]}]}
2016-09-28 20:28:20.182 [error] <0.5423.0> gen_server 'Elixir.Perf.Runner.RunServer' terminated with reason: #{'__exception__' => true,'__struct__' => 'Elixir.Ecto.InvalidChangesetError',action => update,changeset => #{'__struct__' => 'Elixir.Ecto.Changeset',action => update,changes => #{finished_at => #{'__struct__' => 'Elixir.Ecto.DateTime',day => 29,hour => 3,min => 28,month => 9,sec => 20,usec => 0,year => 2016},status => #{'__struct__' => 'Elixir.Ecto.Changeset',action => update,changes => #{raw => <<"foo">>,type => <<"failed">>},constraints => [],data => #{'__meta__' => #{'__struct__' => 'Elixir.Ecto.Schema.Metadata',...},...},...}},...}} in 'Elixir.Ecto.Repo.Schema':'update!'/4 line 132
2016-09-28 20:28:20.183 [error] <0.5423.0> CRASH REPORT Process 'Elixir.Perf.Runner.RunServer' with 0 neighbours exited with reason: #{'__exception__' => true,'__struct__' => 'Elixir.Ecto.InvalidChangesetError',action => update,changeset => #{'__struct__' => 'Elixir.Ecto.Changeset',action => update,changes => #{finished_at => #{'__struct__' => 'Elixir.Ecto.DateTime',day => 29,hour => 3,min => 28,month => 9,sec => 20,usec => 0,year => 2016},status => #{'__struct__' => 'Elixir.Ecto.Changeset',action => update,changes => #{raw => <<"foo">>,type => <<"failed">>},constraints => [],data => #{'__meta__' => #{'__struct__' => 'Elixir.Ecto.Schema.Metadata',...},...},...}},...}} in 'Elixir.Ecto.Repo.Schema':'update!'/4 line 132 in gen_server:terminate/7 line 826
2016-09-28 20:28:20.184 [error] <0.420.0> Supervisor 'Elixir.Perf.Runner' had child undefined started with 'Elixir.Perf.Runner.RunServer':start_link() at <0.5423.0> exit with reason #{'__exception__' => true,'__struct__' => 'Elixir.Ecto.InvalidChangesetError',action => update,changeset => #{'__struct__' => 'Elixir.Ecto.Changeset',action => update,changes => #{finished_at => #{'__struct__' => 'Elixir.Ecto.DateTime',day => 29,hour => 3,min => 28,month => 9,sec => 20,usec => 0,year => 2016},status => #{'__struct__' => 'Elixir.Ecto.Changeset',action => update,changes => #{raw => <<"foo">>,type => <<"failed">>},constraints => [],data => #{'__meta__' => #{'__struct__' => 'Elixir.Ecto.Schema.Metadata',...},...},...}},...}} in 'Elixir.Ecto.Repo.Schema':'update!'/4 line 132 in context child_terminated
2016-09-28 20:28:20.783 [error] <0.5511.0> CRASH REPORT Process <0.5511.0> with 0 neighbours exited with reason: no function clause matching 'Elixir.IO':chardata_to_string(nil) line 412 in gen_server:init_it/6 line 352
2016-09-28 20:28:20.790 [error] <0.316.0> Ranch listener 'Elixir.Perf.Endpoint.HTTP' had connection process started with cowboy_protocol:start_link/4 at <0.5498.0> exit with reason: {{#{'__exception__' => true,'__struct__' => 'Elixir.Poison.EncodeError',message => nil,value => <0.5510.0>},[{'Elixir.Poison.Encoder.Any',encode,2,[{file,"lib/poison/encoder.ex"},{line,354}]},{'Elixir.Poison.Encoder.Map','-encode/3-fun-1-',4,[{file,"lib/poison/encoder.ex"},{line,213}]},{'Elixir.Poison.Encoder.Map','-encode/3-lists^foldl/2-0-',3,[{file,"lib/poison/encoder.ex"},{line,214}]},{'Elixir.Poison.Encoder.Map',encode,3,[{file,"lib/poison/encoder.ex"},{line,214}]},{'Elixir.Poison.Encoder.Map','-encode/3-fun-1-',4,[{file,"lib/poison/encoder.ex"},{line,213}]},{'Elixir.Poison.Encoder.Map','-encode/3-lists^foldl/2-0-',3,[{file,"lib/poison/encoder.ex"},{line,214}]},{'Elixir.Poison.Encoder.Map',encode,3,[{file,"lib/poison/encoder.ex"},{line,214}]},{'Elixir.Poison.Encoder.Map','-encode/3-fun-1-',4,[{file,"lib/poison/encoder.ex"},{line,213}]},{'Elixir.Poison.Encoder.Map','-encode/3-lists^foldl/2-0-',3,[{file,"lib/poison/encoder.ex"},{line,214}]},{'Elixir.Poison.Encoder.Map',encode,3,[{file,"lib/poison/encoder.ex"},{line,214}]},{'Elixir.Poison','encode!',2,[{file,"lib/poison.ex"},{line,41}]},{'Elixir.Phoenix.Transports.WebSocketSerializer','encode!',1,[{file,"lib/phoenix/transports/websocket_serializer.ex"},{line,25}]},{'Elixir.Phoenix.Transports.WebSocket',encode_reply,2,[{file,"lib/phoenix/transports/websocket.ex"},{line,171}]},{'Elixir.Phoenix.Endpoint.CowboyWebSocket',websocket_handle,3,[{file,"lib/phoenix/endpoint/cowboy_websocket.ex"},{line,77}]},{cowboy_websocket,handler_call,7,[{file,"src/cowboy_websocket.erl"},{line,588}]},{'Elixir.Phoenix.Endpoint.CowboyWebSocket',resume,3,[{file,"lib/phoenix/endpoint/cowboy_websocket.ex"},{line,49}]},{cowboy_protocol,execute,4,[{file,"src/cowboy_protocol.erl"},{line,442}]}]},{'Elixir.Phoenix.Endpoint.CowboyWebSocket',resume,[]}}
2016-09-28 20:28:23.799 [error] <0.5520.0> CRASH REPORT Process <0.5520.0> with 0 neighbours exited with reason: no function clause matching 'Elixir.IO':chardata_to_string(nil) line 412 in gen_server:init_it/6 line 352
2016-09-28 20:28:23.804 [error] <0.316.0> Ranch listener 'Elixir.Perf.Endpoint.HTTP' had connection process started with cowboy_protocol:start_link/4 at <0.5512.0> exit with reason: {{#{'__exception__' => true,'__struct__' => 'Elixir.Poison.EncodeError',message => nil,value => <0.5519.0>},[{'Elixir.Poison.Encoder.Any',encode,2,[{file,"lib/poison/encoder.ex"},{line,354}]},{'Elixir.Poison.Encoder.Map','-encode/3-fun-1-',4,[{file,"lib/poison/encoder.ex"},{line,213}]},{'Elixir.Poison.Encoder.Map','-encode/3-lists^foldl/2-0-',3,[{file,"lib/poison/encoder.ex"},{line,214}]},{'Elixir.Poison.Encoder.Map',encode,3,[{file,"lib/poison/encoder.ex"},{line,214}]},{'Elixir.Poison.Encoder.Map','-encode/3-fun-1-',4,[{file,"lib/poison/encoder.ex"},{line,213}]},{'Elixir.Poison.Encoder.Map','-encode/3-lists^foldl/2-0-',3,[{file,"lib/poison/encoder.ex"},{line,214}]},{'Elixir.Poison.Encoder.Map',encode,3,[{file,"lib/poison/encoder.ex"},{line,214}]},{'Elixir.Poison.Encoder.Map','-encode/3-fun-1-',4,[{file,"lib/poison/encoder.ex"},{line,213}]},{'Elixir.Poison.Encoder.Map','-encode/3-lists^foldl/2-0-',3,[{file,"lib/poison/encoder.ex"},{line,214}]},{'Elixir.Poison.Encoder.Map',encode,3,[{file,"lib/poison/encoder.ex"},{line,214}]},{'Elixir.Poison','encode!',2,[{file,"lib/poison.ex"},{line,41}]},{'Elixir.Phoenix.Transports.WebSocketSerializer','encode!',1,[{file,"lib/phoenix/transports/websocket_serializer.ex"},{line,25}]},{'Elixir.Phoenix.Transports.WebSocket',encode_reply,2,[{file,"lib/phoenix/transports/websocket.ex"},{line,171}]},{'Elixir.Phoenix.Endpoint.CowboyWebSocket',websocket_handle,3,[{file,"lib/phoenix/endpoint/cowboy_websocket.ex"},{line,77}]},{cowboy_websocket,handler_call,7,[{file,"src/cowboy_websocket.erl"},{line,588}]},{'Elixir.Phoenix.Endpoint.CowboyWebSocket',resume,3,[{file,"lib/phoenix/endpoint/cowboy_websocket.ex"},{line,49}]},{cowboy_protocol,execute,4,[{file,"src/cowboy_protocol.erl"},{line,442}]}]},{'Elixir.Phoenix.Endpoint.CowboyWebSocket',resume,[]}}
2016-09-28 20:28:28.806 [error] <0.5529.0> CRASH REPORT Process <0.5529.0> with 0 neighbours exited with reason: no function clause matching 'Elixir.IO':chardata_to_string(nil) line 412 in gen_server:init_it/6 line 352
2016-09-28 20:28:28.815 [error] <0.316.0> Ranch listener 'Elixir.Perf.Endpoint.HTTP' had connection process started with cowboy_protocol:start_link/4 at <0.5521.0> exit with reason: {{#{'__exception__' => true,'__struct__' => 'Elixir.Poison.EncodeError',message => nil,value => <0.5528.0>},[{'Elixir.Poison.Encoder.Any',encode,2,[{file,"lib/poison/encoder.ex"},{line,354}]},{'Elixir.Poison.Encoder.Map','-encode/3-fun-1-',4,[{file,"lib/poison/encoder.ex"},{line,213}]},{'Elixir.Poison.Encoder.Map','-encode/3-lists^foldl/2-0-',3,[{file,"lib/poison/encoder.ex"},{line,214}]},{'Elixir.Poison.Encoder.Map',encode,3,[{file,"lib/poison/encoder.ex"},{line,214}]},{'Elixir.Poison.Encoder.Map','-encode/3-fun-1-',4,[{file,"lib/poison/encoder.ex"},{line,213}]},{'Elixir.Poison.Encoder.Map','-encode/3-lists^foldl/2-0-',3,[{file,"lib/poison/encoder.ex"},{line,214}]},{'Elixir.Poison.Encoder.Map',encode,3,[{file,"lib/poison/encoder.ex"},{line,214}]},{'Elixir.Poison.Encoder.Map','-encode/3-fun-1-',4,[{file,"lib/poison/encoder.ex"},{line,213}]},{'Elixir.Poison.Encoder.Map','-encode/3-lists^foldl/2-0-',3,[{file,"lib/poison/encoder.ex"},{line,214}]},{'Elixir.Poison.Encoder.Map',encode,3,[{file,"lib/poison/encoder.ex"},{line,214}]},{'Elixir.Poison','encode!',2,[{file,"lib/poison.ex"},{line,41}]},{'Elixir.Phoenix.Transports.WebSocketSerializer','encode!',1,[{file,"lib/phoenix/transports/websocket_serializer.ex"},{line,25}]},{'Elixir.Phoenix.Transports.WebSocket',encode_reply,2,[{file,"lib/phoenix/transports/websocket.ex"},{line,171}]},{'Elixir.Phoenix.Endpoint.CowboyWebSocket',websocket_handle,3,[{file,"lib/phoenix/endpoint/cowboy_websocket.ex"},{line,77}]},{cowboy_websocket,handler_call,7,[{file,"src/cowboy_websocket.erl"},{line,588}]},{'Elixir.Phoenix.Endpoint.CowboyWebSocket',resume,3,[{file,"lib/phoenix/endpoint/cowboy_websocket.ex"},{line,49}]},{cowboy_protocol,execute,4,[{file,"src/cowboy_protocol.erl"},{line,442}]}]},{'Elixir.Phoenix.Endpoint.CowboyWebSocket',resume,[]}}
2016-09-28 20:28:38.813 [error] <0.5538.0> CRASH REPORT Process <0.5538.0> with 0 neighbours exited with reason: no function clause matching 'Elixir.IO':chardata_to_string(nil) line 412 in gen_server:init_it/6 line 352
2016-09-28 20:28:38.822 [error] <0.316.0> Ranch listener 'Elixir.Perf.Endpoint.HTTP' had connection process started with cowboy_protocol:start_link/4 at <0.5530.0> exit with reason: {{#{'__exception__' => true,'__struct__' => 'Elixir.Poison.EncodeError',message => nil,value => <0.5537.0>},[{'Elixir.Poison.Encoder.Any',encode,2,[{file,"lib/poison/encoder.ex"},{line,354}]},{'Elixir.Poison.Encoder.Map','-encode/3-fun-1-',4,[{file,"lib/poison/encoder.ex"},{line,213}]},{'Elixir.Poison.Encoder.Map','-encode/3-lists^foldl/2-0-',3,[{file,"lib/poison/encoder.ex"},{line,214}]},{'Elixir.Poison.Encoder.Map',encode,3,[{file,"lib/poison/encoder.ex"},{line,214}]},{'Elixir.Poison.Encoder.Map','-encode/3-fun-1-',4,[{file,"lib/poison/encoder.ex"},{line,213}]},{'Elixir.Poison.Encoder.Map','-encode/3-lists^foldl/2-0-',3,[{file,"lib/poison/encoder.ex"},{line,214}]},{'Elixir.Poison.Encoder.Map',encode,3,[{file,"lib/poison/encoder.ex"},{line,214}]},{'Elixir.Poison.Encoder.Map','-encode/3-fun-1-',4,[{file,"lib/poison/encoder.ex"},{line,213}]},{'Elixir.Poison.Encoder.Map','-encode/3-lists^foldl/2-0-',3,[{file,"lib/poison/encoder.ex"},{line,214}]},{'Elixir.Poison.Encoder.Map',encode,3,[{file,"lib/poison/encoder.ex"},{line,214}]},{'Elixir.Poison','encode!',2,[{file,"lib/poison.ex"},{line,41}]},{'Elixir.Phoenix.Transports.WebSocketSerializer','encode!',1,[{file,"lib/phoenix/transports/websocket_serializer.ex"},{line,25}]},{'Elixir.Phoenix.Transports.WebSocket',encode_reply,2,[{file,"lib/phoenix/transports/websocket.ex"},{line,171}]},{'Elixir.Phoenix.Endpoint.CowboyWebSocket',websocket_handle,3,[{file,"lib/phoenix/endpoint/cowboy_websocket.ex"},{line,77}]},{cowboy_websocket,handler_call,7,[{file,"src/cowboy_websocket.erl"},{line,588}]},{'Elixir.Phoenix.Endpoint.CowboyWebSocket',resume,3,[{file,"lib/phoenix/endpoint/cowboy_websocket.ex"},{line,49}]},{cowboy_protocol,execute,4,[{file,"src/cowboy_protocol.erl"},{line,442}]}]},{'Elixir.Phoenix.Endpoint.CowboyWebSocket',resume,[]}}
2016-09-28 20:28:48.820 [error] <0.5547.0> CRASH REPORT Process <0.5547.0> with 0 neighbours exited with reason: no function clause matching 'Elixir.IO':chardata_to_string(nil) line 412 in gen_server:init_it/6 line 352
2016-09-28 20:28:48.827 [error] <0.316.0> Ranch listener 'Elixir.Perf.Endpoint.HTTP' had connection process started with cowboy_protocol:start_link/4 at <0.5539.0> exit with reason: {{#{'__exception__' => true,'__struct__' => 'Elixir.Poison.EncodeError',message => nil,value => <0.5546.0>},[{'Elixir.Poison.Encoder.Any',encode,2,[{file,"lib/poison/encoder.ex"},{line,354}]},{'Elixir.Poison.Encoder.Map','-encode/3-fun-1-',4,[{file,"lib/poison/encoder.ex"},{line,213}]},{'Elixir.Poison.Encoder.Map','-encode/3-lists^foldl/2-0-',3,[{file,"lib/poison/encoder.ex"},{line,214}]},{'Elixir.Poison.Encoder.Map',encode,3,[{file,"lib/poison/encoder.ex"},{line,214}]},{'Elixir.Poison.Encoder.Map','-encode/3-fun-1-',4,[{file,"lib/poison/encoder.ex"},{line,213}]},{'Elixir.Poison.Encoder.Map','-encode/3-lists^foldl/2-0-',3,[{file,"lib/poison/encoder.ex"},{line,214}]},{'Elixir.Poison.Encoder.Map',encode,3,[{file,"lib/poison/encoder.ex"},{line,214}]},{'Elixir.Poison.Encoder.Map','-encode/3-fun-1-',4,[{file,"lib/poison/encoder.ex"},{line,213}]},{'Elixir.Poison.Encoder.Map','-encode/3-lists^foldl/2-0-',3,[{file,"lib/poison/encoder.ex"},{line,214}]},{'Elixir.Poison.Encoder.Map',encode,3,[{file,"lib/poison/encoder.ex"},{line,214}]},{'Elixir.Poison','encode!',2,[{file,"lib/poison.ex"},{line,41}]},{'Elixir.Phoenix.Transports.WebSocketSerializer','encode!',1,[{file,"lib/phoenix/transports/websocket_serializer.ex"},{line,25}]},{'Elixir.Phoenix.Transports.WebSocket',encode_reply,2,[{file,"lib/phoenix/transports/websocket.ex"},{line,171}]},{'Elixir.Phoenix.Endpoint.CowboyWebSocket',websocket_handle,3,[{file,"lib/phoenix/endpoint/cowboy_websocket.ex"},{line,77}]},{cowboy_websocket,handler_call,7,[{file,"src/cowboy_websocket.erl"},{line,588}]},{'Elixir.Phoenix.Endpoint.CowboyWebSocket',resume,3,[{file,"lib/phoenix/endpoint/cowboy_websocket.ex"},{line,49}]},{cowboy_protocol,execute,4,[{file,"src/cowboy_protocol.erl"},{line,442}]}]},{'Elixir.Phoenix.Endpoint.CowboyWebSocket',resume,[]}}
2016-09-28 20:28:58.826 [error] <0.5556.0> CRASH REPORT Process <0.5556.0> with 0 neighbours exited with reason: no function clause matching 'Elixir.IO':chardata_to_string(nil) line 412 in gen_server:init_it/6 line 352
2016-09-28 20:28:58.830 [error] <0.316.0> Ranch listener 'Elixir.Perf.Endpoint.HTTP' had connection process started with cowboy_protocol:start_link/4 at <0.5548.0> exit with reason: {{#{'__exception__' => true,'__struct__' => 'Elixir.Poison.EncodeError',message => nil,value => <0.5555.0>},[{'Elixir.Poison.Encoder.Any',encode,2,[{file,"lib/poison/encoder.ex"},{line,354}]},{'Elixir.Poison.Encoder.Map','-encode/3-fun-1-',4,[{file,"lib/poison/encoder.ex"},{line,213}]},{'Elixir.Poison.Encoder.Map','-encode/3-lists^foldl/2-0-',3,[{file,"lib/poison/encoder.ex"},{line,214}]},{'Elixir.Poison.Encoder.Map',encode,3,[{file,"lib/poison/encoder.ex"},{line,214}]},{'Elixir.Poison.Encoder.Map','-encode/3-fun-1-',4,[{file,"lib/poison/encoder.ex"},{line,213}]},{'Elixir.Poison.Encoder.Map','-encode/3-lists^foldl/2-0-',3,[{file,"lib/poison/encoder.ex"},{line,214}]},{'Elixir.Poison.Encoder.Map',encode,3,[{file,"lib/poison/encoder.ex"},{line,214}]},{'Elixir.Poison.Encoder.Map','-encode/3-fun-1-',4,[{file,"lib/poison/encoder.ex"},{line,213}]},{'Elixir.Poison.Encoder.Map','-encode/3-lists^foldl/2-0-',3,[{file,"lib/poison/encoder.ex"},{line,214}]},{'Elixir.Poison.Encoder.Map',encode,3,[{file,"lib/poison/encoder.ex"},{line,214}]},{'Elixir.Poison','encode!',2,[{file,"lib/poison.ex"},{line,41}]},{'Elixir.Phoenix.Transports.WebSocketSerializer','encode!',1,[{file,"lib/phoenix/transports/websocket_serializer.ex"},{line,25}]},{'Elixir.Phoenix.Transports.WebSocket',encode_reply,2,[{file,"lib/phoenix/transports/websocket.ex"},{line,171}]},{'Elixir.Phoenix.Endpoint.CowboyWebSocket',websocket_handle,3,[{file,"lib/phoenix/endpoint/cowboy_websocket.ex"},{line,77}]},{cowboy_websocket,handler_call,7,[{file,"src/cowboy_websocket.erl"},{line,588}]},{'Elixir.Phoenix.Endpoint.CowboyWebSocket',resume,3,[{file,"lib/phoenix/endpoint/cowboy_websocket.ex"},{line,49}]},{cowboy_protocol,execute,4,[{file,"src/cowboy_protocol.erl"},{line,442}]}]},{'Elixir.Phoenix.Endpoint.CowboyWebSocket',resume,[]}}
2016-09-28 20:29:08.832 [error] <0.5565.0> CRASH REPORT Process <0.5565.0> with 0 neighbours exited with reason: no function clause matching 'Elixir.IO':chardata_to_string(nil) line 412 in gen_server:init_it/6 line 352
2016-09-28 20:29:08.839 [error] <0.316.0> Ranch listener 'Elixir.Perf.Endpoint.HTTP' had connection process started with cowboy_protocol:start_link/4 at <0.5557.0> exit with reason: {{#{'__exception__' => true,'__struct__' => 'Elixir.Poison.EncodeError',message => nil,value => <0.5564.0>},[{'Elixir.Poison.Encoder.Any',encode,2,[{file,"lib/poison/encoder.ex"},{line,354}]},{'Elixir.Poison.Encoder.Map','-encode/3-fun-1-',4,[{file,"lib/poison/encoder.ex"},{line,213}]},{'Elixir.Poison.Encoder.Map','-encode/3-lists^foldl/2-0-',3,[{file,"lib/poison/encoder.ex"},{line,214}]},{'Elixir.Poison.Encoder.Map',encode,3,[{file,"lib/poison/encoder.ex"},{line,214}]},{'Elixir.Poison.Encoder.Map','-encode/3-fun-1-',4,[{file,"lib/poison/encoder.ex"},{line,213}]},{'Elixir.Poison.Encoder.Map','-encode/3-lists^foldl/2-0-',3,[{file,"lib/poison/encoder.ex"},{line,214}]},{'Elixir.Poison.Encoder.Map',encode,3,[{file,"lib/poison/encoder.ex"},{line,214}]},{'Elixir.Poison.Encoder.Map','-encode/3-fun-1-',4,[{file,"lib/poison/encoder.ex"},{line,213}]},{'Elixir.Poison.Encoder.Map','-encode/3-lists^foldl/2-0-',3,[{file,"lib/poison/encoder.ex"},{line,214}]},{'Elixir.Poison.Encoder.Map',encode,3,[{file,"lib/poison/encoder.ex"},{line,214}]},{'Elixir.Poison','encode!',2,[{file,"lib/poison.ex"},{line,41}]},{'Elixir.Phoenix.Transports.WebSocketSerializer','encode!',1,[{file,"lib/phoenix/transports/websocket_serializer.ex"},{line,25}]},{'Elixir.Phoenix.Transports.WebSocket',encode_reply,2,[{file,"lib/phoenix/transports/websocket.ex"},{line,171}]},{'Elixir.Phoenix.Endpoint.CowboyWebSocket',websocket_handle,3,[{file,"lib/phoenix/endpoint/cowboy_websocket.ex"},{line,77}]},{cowboy_websocket,handler_call,7,[{file,"src/cowboy_websocket.erl"},{line,588}]},{'Elixir.Phoenix.Endpoint.CowboyWebSocket',resume,3,[{file,"lib/phoenix/endpoint/cowboy_websocket.ex"},{line,49}]},{cowboy_protocol,execute,4,[{file,"src/cowboy_protocol.erl"},{line,442}]}]},{'Elixir.Phoenix.Endpoint.CowboyWebSocket',resume,[]}}
2016-09-28 20:29:18.838 [error] <0.5574.0> CRASH REPORT Process <0.5574.0> with 0 neighbours exited with reason: no function clause matching 'Elixir.IO':chardata_to_string(nil) line 412 in gen_server:init_it/6 line 352
2016-09-28 20:29:18.845 [error] <0.316.0> Ranch listener 'Elixir.Perf.Endpoint.HTTP' had connection process started with cowboy_protocol:start_link/4 at <0.5566.0> exit with reason: {{#{'__exception__' => true,'__struct__' => 'Elixir.Poison.EncodeError',message => nil,value => <0.5573.0>},[{'Elixir.Poison.Encoder.Any',encode,2,[{file,"lib/poison/encoder.ex"},{line,354}]},{'Elixir.Poison.Encoder.Map','-encode/3-fun-1-',4,[{file,"lib/poison/encoder.ex"},{line,213}]},{'Elixir.Poison.Encoder.Map','-encode/3-lists^foldl/2-0-',3,[{file,"lib/poison/encoder.ex"},{line,214}]},{'Elixir.Poison.Encoder.Map',encode,3,[{file,"lib/poison/encoder.ex"},{line,214}]},{'Elixir.Poison.Encoder.Map','-encode/3-fun-1-',4,[{file,"lib/poison/encoder.ex"},{line,213}]},{'Elixir.Poison.Encoder.Map','-encode/3-lists^foldl/2-0-',3,[{file,"lib/poison/encoder.ex"},{line,214}]},{'Elixir.Poison.Encoder.Map',encode,3,[{file,"lib/poison/encoder.ex"},{line,214}]},{'Elixir.Poison.Encoder.Map','-encode/3-fun-1-',4,[{file,"lib/poison/encoder.ex"},{line,213}]},{'Elixir.Poison.Encoder.Map','-encode/3-lists^foldl/2-0-',3,[{file,"lib/poison/encoder.ex"},{line,214}]},{'Elixir.Poison.Encoder.Map',encode,3,[{file,"lib/poison/encoder.ex"},{line,214}]},{'Elixir.Poison','encode!',2,[{file,"lib/poison.ex"},{line,41}]},{'Elixir.Phoenix.Transports.WebSocketSerializer','encode!',1,[{file,"lib/phoenix/transports/websocket_serializer.ex"},{line,25}]},{'Elixir.Phoenix.Transports.WebSocket',encode_reply,2,[{file,"lib/phoenix/transports/websocket.ex"},{line,171}]},{'Elixir.Phoenix.Endpoint.CowboyWebSocket',websocket_handle,3,[{file,"lib/phoenix/endpoint/cowboy_websocket.ex"},{line,77}]},{cowboy_websocket,handler_call,7,[{file,"src/cowboy_websocket.erl"},{line,588}]},{'Elixir.Phoenix.Endpoint.CowboyWebSocket',resume,3,[{file,"lib/phoenix/endpoint/cowboy_websocket.ex"},{line,49}]},{cowboy_protocol,execute,4,[{file,"src/cowboy_protocol.erl"},{line,442}]}]},{'Elixir.Phoenix.Endpoint.CowboyWebSocket',resume,[]}}
2016-09-28 20:29:28.845 [error] <0.5583.0> CRASH REPORT Process <0.5583.0> with 0 neighbours exited with reason: no function clause matching 'Elixir.IO':chardata_to_string(nil) line 412 in gen_server:init_it/6 line 352
2016-09-28 20:29:28.853 [error] <0.316.0> Ranch listener 'Elixir.Perf.Endpoint.HTTP' had connection process started with cowboy_protocol:start_link/4 at <0.5575.0> exit with reason: {{#{'__exception__' => true,'__struct__' => 'Elixir.Poison.EncodeError',message => nil,value => <0.5582.0>},[{'Elixir.Poison.Encoder.Any',encode,2,[{file,"lib/poison/encoder.ex"},{line,354}]},{'Elixir.Poison.Encoder.Map','-encode/3-fun-1-',4,[{file,"lib/poison/encoder.ex"},{line,213}]},{'Elixir.Poison.Encoder.Map','-encode/3-lists^foldl/2-0-',3,[{file,"lib/poison/encoder.ex"},{line,214}]},{'Elixir.Poison.Encoder.Map',encode,3,[{file,"lib/poison/encoder.ex"},{line,214}]},{'Elixir.Poison.Encoder.Map','-encode/3-fun-1-',4,[{file,"lib/poison/encoder.ex"},{line,213}]},{'Elixir.Poison.Encoder.Map','-encode/3-lists^foldl/2-0-',3,[{file,"lib/poison/encoder.ex"},{line,214}]},{'Elixir.Poison.Encoder.Map',encode,3,[{file,"lib/poison/encoder.ex"},{line,214}]},{'Elixir.Poison.Encoder.Map','-encode/3-fun-1-',4,[{file,"lib/poison/encoder.ex"},{line,213}]},{'Elixir.Poison.Encoder.Map','-encode/3-lists^foldl/2-0-',3,[{file,"lib/poison/encoder.ex"},{line,214}]},{'Elixir.Poison.Encoder.Map',encode,3,[{file,"lib/poison/encoder.ex"},{line,214}]},{'Elixir.Poison','encode!',2,[{file,"lib/poison.ex"},{line,41}]},{'Elixir.Phoenix.Transports.WebSocketSerializer','encode!',1,[{file,"lib/phoenix/transports/websocket_serializer.ex"},{line,25}]},{'Elixir.Phoenix.Transports.WebSocket',encode_reply,2,[{file,"lib/phoenix/transports/websocket.ex"},{line,171}]},{'Elixir.Phoenix.Endpoint.CowboyWebSocket',websocket_handle,3,[{file,"lib/phoenix/endpoint/cowboy_websocket.ex"},{line,77}]},{cowboy_websocket,handler_call,7,[{file,"src/cowboy_websocket.erl"},{line,588}]},{'Elixir.Phoenix.Endpoint.CowboyWebSocket',resume,3,[{file,"lib/phoenix/endpoint/cowboy_websocket.ex"},{line,49}]},{cowboy_protocol,execute,4,[{file,"src/cowboy_protocol.erl"},{line,442}]}]},{'Elixir.Phoenix.Endpoint.CowboyWebSocket',resume,[]}}
2016-09-28 20:29:38.852 [error] <0.5592.0> CRASH REPORT Process <0.5592.0> with 0 neighbours exited with reason: no function clause matching 'Elixir.IO':chardata_to_string(nil) line 412 in gen_server:init_it/6 line 352
2016-09-28 20:29:38.860 [error] <0.316.0> Ranch listener 'Elixir.Perf.Endpoint.HTTP' had connection process started with cowboy_protocol:start_link/4 at <0.5584.0> exit with reason: {{#{'__exception__' => true,'__struct__' => 'Elixir.Poison.EncodeError',message => nil,value => <0.5591.0>},[{'Elixir.Poison.Encoder.Any',encode,2,[{file,"lib/poison/encoder.ex"},{line,354}]},{'Elixir.Poison.Encoder.Map','-encode/3-fun-1-',4,[{file,"lib/poison/encoder.ex"},{line,213}]},{'Elixir.Poison.Encoder.Map','-encode/3-lists^foldl/2-0-',3,[{file,"lib/poison/encoder.ex"},{line,214}]},{'Elixir.Poison.Encoder.Map',encode,3,[{file,"lib/poison/encoder.ex"},{line,214}]},{'Elixir.Poison.Encoder.Map','-encode/3-fun-1-',4,[{file,"lib/poison/encoder.ex"},{line,213}]},{'Elixir.Poison.Encoder.Map','-encode/3-lists^foldl/2-0-',3,[{file,"lib/poison/encoder.ex"},{line,214}]},{'Elixir.Poison.Encoder.Map',encode,3,[{file,"lib/poison/encoder.ex"},{line,214}]},{'Elixir.Poison.Encoder.Map','-encode/3-fun-1-',4,[{file,"lib/poison/encoder.ex"},{line,213}]},{'Elixir.Poison.Encoder.Map','-encode/3-lists^foldl/2-0-',3,[{file,"lib/poison/encoder.ex"},{line,214}]},{'Elixir.Poison.Encoder.Map',encode,3,[{file,"lib/poison/encoder.ex"},{line,214}]},{'Elixir.Poison','encode!',2,[{file,"lib/poison.ex"},{line,41}]},{'Elixir.Phoenix.Transports.WebSocketSerializer','encode!',1,[{file,"lib/phoenix/transports/websocket_serializer.ex"},{line,25}]},{'Elixir.Phoenix.Transports.WebSocket',encode_reply,2,[{file,"lib/phoenix/transports/websocket.ex"},{line,171}]},{'Elixir.Phoenix.Endpoint.CowboyWebSocket',websocket_handle,3,[{file,"lib/phoenix/endpoint/cowboy_websocket.ex"},{line,77}]},{cowboy_websocket,handler_call,7,[{file,"src/cowboy_websocket.erl"},{line,588}]},{'Elixir.Phoenix.Endpoint.CowboyWebSocket',resume,3,[{file,"lib/phoenix/endpoint/cowboy_websocket.ex"},{line,49}]},{cowboy_protocol,execute,4,[{file,"src/cowboy_protocol.erl"},{line,442}]}]},{'Elixir.Phoenix.Endpoint.CowboyWebSocket',resume,[]}}
2016-09-28 20:29:48.857 [error] <0.5601.0> CRASH REPORT Process <0.5601.0> with 0 neighbours exited with reason: no function clause matching 'Elixir.IO':chardata_to_string(nil) line 412 in gen_server:init_it/6 line 352
2016-09-28 20:29:48.863 [error] <0.316.0> Ranch listener 'Elixir.Perf.Endpoint.HTTP' had connection process started with cowboy_protocol:start_link/4 at <0.5593.0> exit with reason: {{#{'__exception__' => true,'__struct__' => 'Elixir.Poison.EncodeError',message => nil,value => <0.5600.0>},[{'Elixir.Poison.Encoder.Any',encode,2,[{file,"lib/poison/encoder.ex"},{line,354}]},{'Elixir.Poison.Encoder.Map','-encode/3-fun-1-',4,[{file,"lib/poison/encoder.ex"},{line,213}]},{'Elixir.Poison.Encoder.Map','-encode/3-lists^foldl/2-0-',3,[{file,"lib/poison/encoder.ex"},{line,214}]},{'Elixir.Poison.Encoder.Map',encode,3,[{file,"lib/poison/encoder.ex"},{line,214}]},{'Elixir.Poison.Encoder.Map','-encode/3-fun-1-',4,[{file,"lib/poison/encoder.ex"},{line,213}]},{'Elixir.Poison.Encoder.Map','-encode/3-lists^foldl/2-0-',3,[{file,"lib/poison/encoder.ex"},{line,214}]},{'Elixir.Poison.Encoder.Map',encode,3,[{file,"lib/poison/encoder.ex"},{line,214}]},{'Elixir.Poison.Encoder.Map','-encode/3-fun-1-',4,[{file,"lib/poison/encoder.ex"},{line,213}]},{'Elixir.Poison.Encoder.Map','-encode/3-lists^foldl/2-0-',3,[{file,"lib/poison/encoder.ex"},{line,214}]},{'Elixir.Poison.Encoder.Map',encode,3,[{file,"lib/poison/encoder.ex"},{line,214}]},{'Elixir.Poison','encode!',2,[{file,"lib/poison.ex"},{line,41}]},{'Elixir.Phoenix.Transports.WebSocketSerializer','encode!',1,[{file,"lib/phoenix/transports/websocket_serializer.ex"},{line,25}]},{'Elixir.Phoenix.Transports.WebSocket',encode_reply,2,[{file,"lib/phoenix/transports/websocket.ex"},{line,171}]},{'Elixir.Phoenix.Endpoint.CowboyWebSocket',websocket_handle,3,[{file,"lib/phoenix/endpoint/cowboy_websocket.ex"},{line,77}]},{cowboy_websocket,handler_call,7,[{file,"src/cowboy_websocket.erl"},{line,588}]},{'Elixir.Phoenix.Endpoint.CowboyWebSocket',resume,3,[{file,"lib/phoenix/endpoint/cowboy_websocket.ex"},{line,49}]},{cowboy_protocol,execute,4,[{file,"src/cowboy_protocol.erl"},{line,442}]}]},{'Elixir.Phoenix.Endpoint.CowboyWebSocket',resume,[]}}
2016-09-28 20:29:58.863 [error] <0.5610.0> CRASH REPORT Process <0.5610.0> with 0 neighbours exited with reason: no function clause matching 'Elixir.IO':chardata_to_string(nil) line 412 in gen_server:init_it/6 line 352
2016-09-28 20:29:58.869 [error] <0.316.0> Ranch listener 'Elixir.Perf.Endpoint.HTTP' had connection process started with cowboy_protocol:start_link/4 at <0.5602.0> exit with reason: {{#{'__exception__' => true,'__struct__' => 'Elixir.Poison.EncodeError',message => nil,value => <0.5609.0>},[{'Elixir.Poison.Encoder.Any',encode,2,[{file,"lib/poison/encoder.ex"},{line,354}]},{'Elixir.Poison.Encoder.Map','-encode/3-fun-1-',4,[{file,"lib/poison/encoder.ex"},{line,213}]},{'Elixir.Poison.Encoder.Map','-encode/3-lists^foldl/2-0-',3,[{file,"lib/poison/encoder.ex"},{line,214}]},{'Elixir.Poison.Encoder.Map',encode,3,[{file,"lib/poison/encoder.ex"},{line,214}]},{'Elixir.Poison.Encoder.Map','-encode/3-fun-1-',4,[{file,"lib/poison/encoder.ex"},{line,213}]},{'Elixir.Poison.Encoder.Map','-encode/3-lists^foldl/2-0-',3,[{file,"lib/poison/encoder.ex"},{line,214}]},{'Elixir.Poison.Encoder.Map',encode,3,[{file,"lib/poison/encoder.ex"},{line,214}]},{'Elixir.Poison.Encoder.Map','-encode/3-fun-1-',4,[{file,"lib/poison/encoder.ex"},{line,213}]},{'Elixir.Poison.Encoder.Map','-encode/3-lists^foldl/2-0-',3,[{file,"lib/poison/encoder.ex"},{line,214}]},{'Elixir.Poison.Encoder.Map',encode,3,[{file,"lib/poison/encoder.ex"},{line,214}]},{'Elixir.Poison','encode!',2,[{file,"lib/poison.ex"},{line,41}]},{'Elixir.Phoenix.Transports.WebSocketSerializer','encode!',1,[{file,"lib/phoenix/transports/websocket_serializer.ex"},{line,25}]},{'Elixir.Phoenix.Transports.WebSocket',encode_reply,2,[{file,"lib/phoenix/transports/websocket.ex"},{line,171}]},{'Elixir.Phoenix.Endpoint.CowboyWebSocket',websocket_handle,3,[{file,"lib/phoenix/endpoint/cowboy_websocket.ex"},{line,77}]},{cowboy_websocket,handler_call,7,[{file,"src/cowboy_websocket.erl"},{line,588}]},{'Elixir.Phoenix.Endpoint.CowboyWebSocket',resume,3,[{file,"lib/phoenix/endpoint/cowboy_websocket.ex"},{line,49}]},{cowboy_protocol,execute,4,[{file,"src/cowboy_protocol.erl"},{line,442}]}]},{'Elixir.Phoenix.Endpoint.CowboyWebSocket',resume,[]}}
2016-09-28 20:30:08.868 [error] <0.5619.0> CRASH REPORT Process <0.5619.0> with 0 neighbours exited with reason: no function clause matching 'Elixir.IO':chardata_to_string(nil) line 412 in gen_server:init_it/6 line 352
2016-09-28 20:30:08.874 [error] <0.316.0> Ranch listener 'Elixir.Perf.Endpoint.HTTP' had connection process started with cowboy_protocol:start_link/4 at <0.5611.0> exit with reason: {{#{'__exception__' => true,'__struct__' => 'Elixir.Poison.EncodeError',message => nil,value => <0.5618.0>},[{'Elixir.Poison.Encoder.Any',encode,2,[{file,"lib/poison/encoder.ex"},{line,354}]},{'Elixir.Poison.Encoder.Map','-encode/3-fun-1-',4,[{file,"lib/poison/encoder.ex"},{line,213}]},{'Elixir.Poison.Encoder.Map','-encode/3-lists^foldl/2-0-',3,[{file,"lib/poison/encoder.ex"},{line,214}]},{'Elixir.Poison.Encoder.Map',encode,3,[{file,"lib/poison/encoder.ex"},{line,214}]},{'Elixir.Poison.Encoder.Map','-encode/3-fun-1-',4,[{file,"lib/poison/encoder.ex"},{line,213}]},{'Elixir.Poison.Encoder.Map','-encode/3-lists^foldl/2-0-',3,[{file,"lib/poison/encoder.ex"},{line,214}]},{'Elixir.Poison.Encoder.Map',encode,3,[{file,"lib/poison/encoder.ex"},{line,214}]},{'Elixir.Poison.Encoder.Map','-encode/3-fun-1-',4,[{file,"lib/poison/encoder.ex"},{line,213}]},{'Elixir.Poison.Encoder.Map','-encode/3-lists^foldl/2-0-',3,[{file,"lib/poison/encoder.ex"},{line,214}]},{'Elixir.Poison.Encoder.Map',encode,3,[{file,"lib/poison/encoder.ex"},{line,214}]},{'Elixir.Poison','encode!',2,[{file,"lib/poison.ex"},{line,41}]},{'Elixir.Phoenix.Transports.WebSocketSerializer','encode!',1,[{file,"lib/phoenix/transports/websocket_serializer.ex"},{line,25}]},{'Elixir.Phoenix.Transports.WebSocket',encode_reply,2,[{file,"lib/phoenix/transports/websocket.ex"},{line,171}]},{'Elixir.Phoenix.Endpoint.CowboyWebSocket',websocket_handle,3,[{file,"lib/phoenix/endpoint/cowboy_websocket.ex"},{line,77}]},{cowboy_websocket,handler_call,7,[{file,"src/cowboy_websocket.erl"},{line,588}]},{'Elixir.Phoenix.Endpoint.CowboyWebSocket',resume,3,[{file,"lib/phoenix/endpoint/cowboy_websocket.ex"},{line,49}]},{cowboy_protocol,execute,4,[{file,"src/cowboy_protocol.erl"},{line,442}]}]},{'Elixir.Phoenix.Endpoint.CowboyWebSocket',resume,[]}}
2016-09-28 20:30:21.442 [error] <0.657.0> Supervisor 'Elixir.Logger.Supervisor' had child undefined started with 'Elixir.Logger.Watcher':watcher(error_logger, 'Elixir.Logger.ErrorHandler', {true,false,500}, link) at <0.662.0> exit with reason normal in context child_terminated
2016-09-28 20:30:56.923 [error] <0.5956.0> gen_server <0.5956.0> terminated with reason: {'module could not be loaded',[{'Elixir.Perf.Yams',key,[],[]},{'Elixir.Perf.Runner.Producer',handle_cast,2,[{file,"lib/perf/runner/producer.ex"},{line,96}]},{gen_server,try_dispatch,4,[{file,"gen_server.erl"},{line,615}]},{gen_server,handle_msg,5,[{file,"gen_server.erl"},{line,681}]},{proc_lib,init_p_do_apply,3,[{file,"proc_lib.erl"},{line,240}]}]}
2016-09-28 20:30:56.923 [error] <0.5956.0> CRASH REPORT Process <0.5956.0> with 0 neighbours exited with reason: call to undefined function 'Elixir.Perf.Yams':key() in gen_server:terminate/7 line 826
2016-09-28 20:31:23.334 [error] <0.249.0> Supervisor 'Elixir.Logger.Supervisor' had child undefined started with 'Elixir.Logger.Watcher':watcher(error_logger, 'Elixir.Logger.ErrorHandler', {true,false,500}, link) at <0.254.0> exit with reason normal in context child_terminated
2016-09-28 20:31:39.928 [error] <0.5548.0> gen_server <0.5548.0> terminated with reason: bad arithmetic expression in 'Elixir.Poison.Encoder.Perf.Run':'-encode/2-fun-0-'/2 line 93
2016-09-28 20:31:39.928 [error] <0.5548.0> CRASH REPORT Process <0.5548.0> with 0 neighbours exited with reason: bad arithmetic expression in 'Elixir.Poison.Encoder.Perf.Run':'-encode/2-fun-0-'/2 line 93 in gen_server:terminate/7 line 826
2016-09-28 20:31:40.003 [error] <0.5559.0> gen_server <0.5559.0> terminated with reason: #{'__exception__' => true,'__struct__' => 'Elixir.ArgumentError',message => <<"ranges (first..last) expect both sides to be integers, got: 0..nil">>} in 'Elixir.Range':new/2 line 55
2016-09-28 20:31:40.003 [error] <0.5559.0> CRASH REPORT Process <0.5559.0> with 0 neighbours exited with reason: #{'__exception__' => true,'__struct__' => 'Elixir.ArgumentError',message => <<"ranges (first..last) expect both sides to be integers, got: 0..nil">>} in 'Elixir.Range':new/2 line 55 in gen_server:terminate/7 line 826
2016-09-28 20:31:40.609 [error] <0.842.0> Supervisor 'Elixir.Logger.Supervisor' had child undefined started with 'Elixir.Logger.Watcher':watcher(error_logger, 'Elixir.Logger.ErrorHandler', {true,false,500}, link) at <0.847.0> exit with reason normal in context child_terminated
2016-09-28 20:31:41.789 [error] emulator Error in process <0.6064.0> with exit value:
{#{'__exception__' => true,'__struct__' => 'Elixir.Postgrex.Error',connection_id => 7933,message => <<"tcp send: closed">>,postgres => nil},[{'Elixir.DBConnection',transaction,3,[{file,"lib/db_connection.ex"},{line,675}]},{'Elixir.Ecto.Repo.Schema','update!',4,[{file,"lib/ecto/repo/schema.ex"},{line,129}]},{'Elixir.Perf.Runner',execute,1,[{file,"lib/perf/runner.ex"},{line,33}]}]}
2016-09-28 20:31:41.791 [error] <0.5943.0> gen_server 'Elixir.Perf.Runner.RunServer' terminated with reason: #{'__exception__' => true,'__struct__' => 'Elixir.Ecto.InvalidChangesetError',action => update,changeset => #{'__struct__' => 'Elixir.Ecto.Changeset',action => update,changes => #{finished_at => #{'__struct__' => 'Elixir.Ecto.DateTime',day => 29,hour => 3,min => 31,month => 9,sec => 41,usec => 0,year => 2016},status => #{'__struct__' => 'Elixir.Ecto.Changeset',action => update,changes => #{raw => <<"foo">>,type => <<"failed">>},constraints => [],data => #{'__meta__' => #{'__struct__' => 'Elixir.Ecto.Schema.Metadata',...},...},...}},...}} in 'Elixir.Ecto.Repo.Schema':'update!'/4 line 132
2016-09-28 20:31:41.791 [error] <0.5943.0> CRASH REPORT Process 'Elixir.Perf.Runner.RunServer' with 0 neighbours exited with reason: #{'__exception__' => true,'__struct__' => 'Elixir.Ecto.InvalidChangesetError',action => update,changeset => #{'__struct__' => 'Elixir.Ecto.Changeset',action => update,changes => #{finished_at => #{'__struct__' => 'Elixir.Ecto.DateTime',day => 29,hour => 3,min => 31,month => 9,sec => 41,usec => 0,year => 2016},status => #{'__struct__' => 'Elixir.Ecto.Changeset',action => update,changes => #{raw => <<"foo">>,type => <<"failed">>},constraints => [],data => #{'__meta__' => #{'__struct__' => 'Elixir.Ecto.Schema.Metadata',...},...},...}},...}} in 'Elixir.Ecto.Repo.Schema':'update!'/4 line 132 in gen_server:terminate/7 line 826
2016-09-28 20:31:41.791 [error] <0.940.0> Supervisor 'Elixir.Perf.Runner' had child undefined started with 'Elixir.Perf.Runner.RunServer':start_link() at <0.5943.0> exit with reason #{'__exception__' => true,'__struct__' => 'Elixir.Ecto.InvalidChangesetError',action => update,changeset => #{'__struct__' => 'Elixir.Ecto.Changeset',action => update,changes => #{finished_at => #{'__struct__' => 'Elixir.Ecto.DateTime',day => 29,hour => 3,min => 31,month => 9,sec => 41,usec => 0,year => 2016},status => #{'__struct__' => 'Elixir.Ecto.Changeset',action => update,changes => #{raw => <<"foo">>,type => <<"failed">>},constraints => [],data => #{'__meta__' => #{'__struct__' => 'Elixir.Ecto.Schema.Metadata',...},...},...}},...}} in 'Elixir.Ecto.Repo.Schema':'update!'/4 line 132 in context child_terminated
2016-09-28 20:32:28.464 [error] <0.218.0> Supervisor 'Elixir.Logger.Supervisor' had child undefined started with 'Elixir.Logger.Watcher':watcher(error_logger, 'Elixir.Logger.ErrorHandler', {true,false,500}, link) at <0.223.0> exit with reason normal in context child_terminated
2016-09-28 20:32:29.726 [error] emulator Error in process <0.5440.0> with exit value:
{#{'__exception__' => true,'__struct__' => 'Elixir.Postgrex.Error',connection_id => 8032,message => <<"tcp send: closed">>,postgres => nil},[{'Elixir.DBConnection',transaction,3,[{file,"lib/db_connection.ex"},{line,675}]},{'Elixir.Ecto.Repo.Schema','update!',4,[{file,"lib/ecto/repo/schema.ex"},{line,129}]},{'Elixir.Perf.Runner',execute,1,[{file,"lib/perf/runner.ex"},{line,33}]}]}
2016-09-28 20:32:29.758 [error] <0.5319.0> gen_server 'Elixir.Perf.Runner.RunServer' terminated with reason: #{'__exception__' => true,'__struct__' => 'Elixir.Ecto.InvalidChangesetError',action => update,changeset => #{'__struct__' => 'Elixir.Ecto.Changeset',action => update,changes => #{finished_at => #{'__struct__' => 'Elixir.Ecto.DateTime',day => 29,hour => 3,min => 32,month => 9,sec => 29,usec => 0,year => 2016},status => #{'__struct__' => 'Elixir.Ecto.Changeset',action => update,changes => #{raw => <<"foo">>,type => <<"failed">>},constraints => [],data => #{'__meta__' => #{'__struct__' => 'Elixir.Ecto.Schema.Metadata',...},...},...}},...}} in 'Elixir.Ecto.Repo.Schema':'update!'/4 line 132
2016-09-28 20:32:29.758 [error] <0.5319.0> CRASH REPORT Process 'Elixir.Perf.Runner.RunServer' with 0 neighbours exited with reason: #{'__exception__' => true,'__struct__' => 'Elixir.Ecto.InvalidChangesetError',action => update,changeset => #{'__struct__' => 'Elixir.Ecto.Changeset',action => update,changes => #{finished_at => #{'__struct__' => 'Elixir.Ecto.DateTime',day => 29,hour => 3,min => 32,month => 9,sec => 29,usec => 0,year => 2016},status => #{'__struct__' => 'Elixir.Ecto.Changeset',action => update,changes => #{raw => <<"foo">>,type => <<"failed">>},constraints => [],data => #{'__meta__' => #{'__struct__' => 'Elixir.Ecto.Schema.Metadata',...},...},...}},...}} in 'Elixir.Ecto.Repo.Schema':'update!'/4 line 132 in gen_server:terminate/7 line 826
2016-09-28 20:32:29.758 [error] <0.316.0> Supervisor 'Elixir.Perf.Runner' had child undefined started with 'Elixir.Perf.Runner.RunServer':start_link() at <0.5319.0> exit with reason #{'__exception__' => true,'__struct__' => 'Elixir.Ecto.InvalidChangesetError',action => update,changeset => #{'__struct__' => 'Elixir.Ecto.Changeset',action => update,changes => #{finished_at => #{'__struct__' => 'Elixir.Ecto.DateTime',day => 29,hour => 3,min => 32,month => 9,sec => 29,usec => 0,year => 2016},status => #{'__struct__' => 'Elixir.Ecto.Changeset',action => update,changes => #{raw => <<"foo">>,type => <<"failed">>},constraints => [],data => #{'__meta__' => #{'__struct__' => 'Elixir.Ecto.Schema.Metadata',...},...},...}},...}} in 'Elixir.Ecto.Repo.Schema':'update!'/4 line 132 in context child_terminated
2016-09-28 20:32:51.302 [error] <0.218.0> Supervisor 'Elixir.Logger.Supervisor' had child undefined started with 'Elixir.Logger.Watcher':watcher(error_logger, 'Elixir.Logger.ErrorHandler', {true,false,500}, link) at <0.223.0> exit with reason normal in context child_terminated
2016-09-28 20:32:52.572 [error] emulator Error in process <0.5440.0> with exit value:
{#{'__exception__' => true,'__struct__' => 'Elixir.Postgrex.Error',connection_id => 8121,message => <<"tcp send: closed">>,postgres => nil},[{'Elixir.DBConnection',transaction,3,[{file,"lib/db_connection.ex"},{line,675}]},{'Elixir.Ecto.Repo.Schema','update!',4,[{file,"lib/ecto/repo/schema.ex"},{line,129}]},{'Elixir.Perf.Runner',execute,1,[{file,"lib/perf/runner.ex"},{line,33}]}]}
2016-09-28 20:32:52.612 [error] <0.5319.0> gen_server 'Elixir.Perf.Runner.RunServer' terminated with reason: #{'__exception__' => true,'__struct__' => 'Elixir.Ecto.InvalidChangesetError',action => update,changeset => #{'__struct__' => 'Elixir.Ecto.Changeset',action => update,changes => #{finished_at => #{'__struct__' => 'Elixir.Ecto.DateTime',day => 29,hour => 3,min => 32,month => 9,sec => 52,usec => 0,year => 2016},status => #{'__struct__' => 'Elixir.Ecto.Changeset',action => update,changes => #{raw => <<"foo">>,type => <<"failed">>},constraints => [],data => #{'__meta__' => #{'__struct__' => 'Elixir.Ecto.Schema.Metadata',...},...},...}},...}} in 'Elixir.Ecto.Repo.Schema':'update!'/4 line 132
2016-09-28 20:32:52.613 [error] <0.5319.0> CRASH REPORT Process 'Elixir.Perf.Runner.RunServer' with 0 neighbours exited with reason: #{'__exception__' => true,'__struct__' => 'Elixir.Ecto.InvalidChangesetError',action => update,changeset => #{'__struct__' => 'Elixir.Ecto.Changeset',action => update,changes => #{finished_at => #{'__struct__' => 'Elixir.Ecto.DateTime',day => 29,hour => 3,min => 32,month => 9,sec => 52,usec => 0,year => 2016},status => #{'__struct__' => 'Elixir.Ecto.Changeset',action => update,changes => #{raw => <<"foo">>,type => <<"failed">>},constraints => [],data => #{'__meta__' => #{'__struct__' => 'Elixir.Ecto.Schema.Metadata',...},...},...}},...}} in 'Elixir.Ecto.Repo.Schema':'update!'/4 line 132 in gen_server:terminate/7 line 826
2016-09-28 20:32:52.613 [error] <0.316.0> Supervisor 'Elixir.Perf.Runner' had child undefined started with 'Elixir.Perf.Runner.RunServer':start_link() at <0.5319.0> exit with reason #{'__exception__' => true,'__struct__' => 'Elixir.Ecto.InvalidChangesetError',action => update,changeset => #{'__struct__' => 'Elixir.Ecto.Changeset',action => update,changes => #{finished_at => #{'__struct__' => 'Elixir.Ecto.DateTime',day => 29,hour => 3,min => 32,month => 9,sec => 52,usec => 0,year => 2016},status => #{'__struct__' => 'Elixir.Ecto.Changeset',action => update,changes => #{raw => <<"foo">>,type => <<"failed">>},constraints => [],data => #{'__meta__' => #{'__struct__' => 'Elixir.Ecto.Schema.Metadata',...},...},...}},...}} in 'Elixir.Ecto.Repo.Schema':'update!'/4 line 132 in context child_terminated
2016-09-28 20:33:06.234 [error] <0.218.0> Supervisor 'Elixir.Logger.Supervisor' had child undefined started with 'Elixir.Logger.Watcher':watcher(error_logger, 'Elixir.Logger.ErrorHandler', {true,false,500}, link) at <0.223.0> exit with reason normal in context child_terminated
2016-09-28 20:33:07.247 [error] <0.5441.0> CRASH REPORT Process <0.5441.0> with 0 neighbours exited with reason: no function clause matching 'Elixir.IO':chardata_to_string(nil) line 412 in gen_server:init_it/6 line 352
2016-09-28 20:33:07.291 [error] <0.5446.0> CRASH REPORT Process <0.5446.0> with 0 neighbours exited with reason: no function clause matching 'Elixir.IO':chardata_to_string(nil) line 412 in gen_server:init_it/6 line 352
2016-09-28 20:33:07.304 [error] <0.5449.0> CRASH REPORT Process <0.5449.0> with 0 neighbours exited with reason: no function clause matching 'Elixir.IO':chardata_to_string(nil) line 412 in gen_server:init_it/6 line 352
2016-09-28 20:33:07.401 [error] emulator Error in process <0.5440.0> with exit value:
{#{'__exception__' => true,'__struct__' => 'Elixir.Ecto.StaleEntryError',message => <<"attempted to update a stale struct:\n\n%Perf.Run{__meta__: #Ecto.Schema.Metadata<:loaded, \"runs\">, finished_at: nil, id: 950, inserted_at: #Ecto.DateTime<2016-09-29 03:33:07>, started_at: nil, status: %Perf.Run.Status{__meta__: #Ecto.Schema.Metadata<:built, \"\">, id: \"0279e47e-6c07-4a19-968b-1e9df503bd57\", raw: nil, reason: nil, type: \"not_started\"}, suite: nil, suite_id: 886, updated_at: #Ecto.DateTime<2016-09-29 03:33:07>, yam_ref: \"6fe8553a-85f5-11e6-9edb-c485082be198\"}\n">>},[{'Elixir.Ecto.Repo.Schema',apply,4,[{file,"lib/ecto/repo/schema.ex"},{line,387}]},{'Elixir.Ecto.Repo.Schema','-do_update/4-fun-0-',12,[{file,"lib/ecto/repo/schema.ex"},{line,251}]},{'Elixir.Ecto.Repo.Schema','-wrap_in_transaction/6-fun-0-',3,[{file,"lib/ecto/repo/schema.ex"},{line,595}]},{'Elixir.Ecto.Adapters.SQL','-do_transaction/3-fun-0-',3,[{file,"lib/ecto/adapters/sql.ex"},{line,472}]},{'Elixir.DBConnection',transaction_run,4,[{file,"lib/db_connection.ex"},{line,973}]},{'Elixir.DBConnection',run_begin,3,[{file,"lib/db_connection.ex"},{line,897}]},{'Elixir.DBConnection',transaction,3,[{file,"lib/db_connection.ex"},{line,671}]},{'Elixir.Ecto.Repo.Schema','update!',4,[{file,"lib/ecto/repo/schema.ex"},{line,129}]},{'Elixir.Perf.Runner',execute,1,[{file,"lib/perf/runner.ex"},{line,33}]}]}
2016-09-28 20:33:07.430 [error] <0.5319.0> gen_server 'Elixir.Perf.Runner.RunServer' terminated with reason: #{'__exception__' => true,'__struct__' => 'Elixir.Ecto.InvalidChangesetError',action => update,changeset => #{'__struct__' => 'Elixir.Ecto.Changeset',action => update,changes => #{finished_at => #{'__struct__' => 'Elixir.Ecto.DateTime',day => 29,hour => 3,min => 33,month => 9,sec => 7,usec => 0,year => 2016},status => #{'__struct__' => 'Elixir.Ecto.Changeset',action => update,changes => #{raw => <<"foo">>,type => <<"failed">>},constraints => [],data => #{'__meta__' => #{'__struct__' => 'Elixir.Ecto.Schema.Metadata',...},...},...}},...}} in 'Elixir.Ecto.Repo.Schema':'update!'/4 line 132
2016-09-28 20:33:07.431 [error] <0.5319.0> CRASH REPORT Process 'Elixir.Perf.Runner.RunServer' with 0 neighbours exited with reason: #{'__exception__' => true,'__struct__' => 'Elixir.Ecto.InvalidChangesetError',action => update,changeset => #{'__struct__' => 'Elixir.Ecto.Changeset',action => update,changes => #{finished_at => #{'__struct__' => 'Elixir.Ecto.DateTime',day => 29,hour => 3,min => 33,month => 9,sec => 7,usec => 0,year => 2016},status => #{'__struct__' => 'Elixir.Ecto.Changeset',action => update,changes => #{raw => <<"foo">>,type => <<"failed">>},constraints => [],data => #{'__meta__' => #{'__struct__' => 'Elixir.Ecto.Schema.Metadata',...},...},...}},...}} in 'Elixir.Ecto.Repo.Schema':'update!'/4 line 132 in gen_server:terminate/7 line 826
2016-09-28 20:33:07.431 [error] <0.316.0> Supervisor 'Elixir.Perf.Runner' had child undefined started with 'Elixir.Perf.Runner.RunServer':start_link() at <0.5319.0> exit with reason #{'__exception__' => true,'__struct__' => 'Elixir.Ecto.InvalidChangesetError',action => update,changeset => #{'__struct__' => 'Elixir.Ecto.Changeset',action => update,changes => #{finished_at => #{'__struct__' => 'Elixir.Ecto.DateTime',day => 29,hour => 3,min => 33,month => 9,sec => 7,usec => 0,year => 2016},status => #{'__struct__' => 'Elixir.Ecto.Changeset',action => update,changes => #{raw => <<"foo">>,type => <<"failed">>},constraints => [],data => #{'__meta__' => #{'__struct__' => 'Elixir.Ecto.Schema.Metadata',...},...},...}},...}} in 'Elixir.Ecto.Repo.Schema':'update!'/4 line 132 in context child_terminated
2016-09-28 20:33:18.654 [error] <0.218.0> Supervisor 'Elixir.Logger.Supervisor' had child undefined started with 'Elixir.Logger.Watcher':watcher(error_logger, 'Elixir.Logger.ErrorHandler', {true,false,500}, link) at <0.223.0> exit with reason normal in context child_terminated
2016-09-28 20:33:19.695 [error] <0.5441.0> CRASH REPORT Process <0.5441.0> with 0 neighbours exited with reason: no function clause matching 'Elixir.IO':chardata_to_string(nil) line 412 in gen_server:init_it/6 line 352
2016-09-28 20:33:19.752 [error] <0.5446.0> CRASH REPORT Process <0.5446.0> with 0 neighbours exited with reason: no function clause matching 'Elixir.IO':chardata_to_string(nil) line 412 in gen_server:init_it/6 line 352
2016-09-28 20:33:19.772 [error] <0.5449.0> CRASH REPORT Process <0.5449.0> with 0 neighbours exited with reason: no function clause matching 'Elixir.IO':chardata_to_string(nil) line 412 in gen_server:init_it/6 line 352
2016-09-28 20:33:19.896 [error] emulator Error in process <0.5440.0> with exit value:
{#{'__exception__' => true,'__struct__' => 'Elixir.Ecto.StaleEntryError',message => <<"attempted to update a stale struct:\n\n%Perf.Run{__meta__: #Ecto.Schema.Metadata<:loaded, \"runs\">, finished_at: nil, id: 983, inserted_at: #Ecto.DateTime<2016-09-29 03:33:19>, started_at: nil, status: %Perf.Run.Status{__meta__: #Ecto.Schema.Metadata<:built, \"\">, id: \"c5b1e39c-a37e-4796-8c8e-760d85d52b4e\", raw: nil, reason: nil, type: \"not_started\"}, suite: nil, suite_id: 891, updated_at: #Ecto.DateTime<2016-09-29 03:33:19>, yam_ref: \"775388a8-85f5-11e6-baf9-c485082be198\"}\n">>},[{'Elixir.Ecto.Repo.Schema',apply,4,[{file,"lib/ecto/repo/schema.ex"},{line,387}]},{'Elixir.Ecto.Repo.Schema','-do_update/4-fun-0-',12,[{file,"lib/ecto/repo/schema.ex"},{line,251}]},{'Elixir.Ecto.Repo.Schema','-wrap_in_transaction/6-fun-0-',3,[{file,"lib/ecto/repo/schema.ex"},{line,595}]},{'Elixir.Ecto.Adapters.SQL','-do_transaction/3-fun-0-',3,[{file,"lib/ecto/adapters/sql.ex"},{line,472}]},{'Elixir.DBConnection',transaction_run,4,[{file,"lib/db_connection.ex"},{line,973}]},{'Elixir.DBConnection',run_begin,3,[{file,"lib/db_connection.ex"},{line,897}]},{'Elixir.DBConnection',transaction,3,[{file,"lib/db_connection.ex"},{line,671}]},{'Elixir.Ecto.Repo.Schema','update!',4,[{file,"lib/ecto/repo/schema.ex"},{line,129}]},{'Elixir.Perf.Runner',execute,1,[{file,"lib/perf/runner.ex"},{line,33}]}]}
2016-09-28 20:33:19.928 [error] <0.5319.0> gen_server 'Elixir.Perf.Runner.RunServer' terminated with reason: #{'__exception__' => true,'__struct__' => 'Elixir.Ecto.InvalidChangesetError',action => update,changeset => #{'__struct__' => 'Elixir.Ecto.Changeset',action => update,changes => #{finished_at => #{'__struct__' => 'Elixir.Ecto.DateTime',day => 29,hour => 3,min => 33,month => 9,sec => 19,usec => 0,year => 2016},status => #{'__struct__' => 'Elixir.Ecto.Changeset',action => update,changes => #{raw => <<"foo">>,type => <<"failed">>},constraints => [],data => #{'__meta__' => #{'__struct__' => 'Elixir.Ecto.Schema.Metadata',...},...},...}},...}} in 'Elixir.Ecto.Repo.Schema':'update!'/4 line 132
2016-09-28 20:33:19.929 [error] <0.5319.0> CRASH REPORT Process 'Elixir.Perf.Runner.RunServer' with 0 neighbours exited with reason: #{'__exception__' => true,'__struct__' => 'Elixir.Ecto.InvalidChangesetError',action => update,changeset => #{'__struct__' => 'Elixir.Ecto.Changeset',action => update,changes => #{finished_at => #{'__struct__' => 'Elixir.Ecto.DateTime',day => 29,hour => 3,min => 33,month => 9,sec => 19,usec => 0,year => 2016},status => #{'__struct__' => 'Elixir.Ecto.Changeset',action => update,changes => #{raw => <<"foo">>,type => <<"failed">>},constraints => [],data => #{'__meta__' => #{'__struct__' => 'Elixir.Ecto.Schema.Metadata',...},...},...}},...}} in 'Elixir.Ecto.Repo.Schema':'update!'/4 line 132 in gen_server:terminate/7 line 826
2016-09-28 20:33:19.929 [error] <0.316.0> Supervisor 'Elixir.Perf.Runner' had child undefined started with 'Elixir.Perf.Runner.RunServer':start_link() at <0.5319.0> exit with reason #{'__exception__' => true,'__struct__' => 'Elixir.Ecto.InvalidChangesetError',action => update,changeset => #{'__struct__' => 'Elixir.Ecto.Changeset',action => update,changes => #{finished_at => #{'__struct__' => 'Elixir.Ecto.DateTime',day => 29,hour => 3,min => 33,month => 9,sec => 19,usec => 0,year => 2016},status => #{'__struct__' => 'Elixir.Ecto.Changeset',action => update,changes => #{raw => <<"foo">>,type => <<"failed">>},constraints => [],data => #{'__meta__' => #{'__struct__' => 'Elixir.Ecto.Schema.Metadata',...},...},...}},...}} in 'Elixir.Ecto.Repo.Schema':'update!'/4 line 132 in context child_terminated
2016-09-28 20:33:44.972 [error] <0.699.0> Supervisor 'Elixir.Logger.Supervisor' had child undefined started with 'Elixir.Logger.Watcher':watcher(error_logger, 'Elixir.Logger.ErrorHandler', {true,false,500}, link) at <0.704.0> exit with reason normal in context child_terminated
2016-09-28 20:43:33.180 [error] <0.648.0> Supervisor 'Elixir.Logger.Supervisor' had child undefined started with 'Elixir.Logger.Watcher':watcher(error_logger, 'Elixir.Logger.ErrorHandler', {true,false,500}, link) at <0.653.0> exit with reason normal in context child_terminated
2016-09-28 20:44:04.606 [error] <0.241.0> Supervisor 'Elixir.Logger.Supervisor' had child undefined started with 'Elixir.Logger.Watcher':watcher(error_logger, 'Elixir.Logger.ErrorHandler', {true,false,500}, link) at <0.246.0> exit with reason normal in context child_terminated
2016-09-28 20:44:58.516 [error] <0.218.0> Supervisor 'Elixir.Logger.Supervisor' had child undefined started with 'Elixir.Logger.Watcher':watcher(error_logger, 'Elixir.Logger.ErrorHandler', {true,false,500}, link) at <0.223.0> exit with reason normal in context child_terminated
2016-09-28 20:45:09.000 [error] <0.241.0> Supervisor 'Elixir.Logger.Supervisor' had child undefined started with 'Elixir.Logger.Watcher':watcher(error_logger, 'Elixir.Logger.ErrorHandler', {true,false,500}, link) at <0.246.0> exit with reason normal in context child_terminated
2016-09-28 20:47:23.634 [error] <0.218.0> Supervisor 'Elixir.Logger.Supervisor' had child undefined started with 'Elixir.Logger.Watcher':watcher(error_logger, 'Elixir.Logger.ErrorHandler', {true,false,500}, link) at <0.223.0> exit with reason normal in context child_terminated
2016-09-28 20:47:43.421 [error] <0.218.0> Supervisor 'Elixir.Logger.Supervisor' had child undefined started with 'Elixir.Logger.Watcher':watcher(error_logger, 'Elixir.Logger.ErrorHandler', {true,false,500}, link) at <0.223.0> exit with reason normal in context child_terminated
2016-09-28 20:48:02.410 [error] <0.218.0> Supervisor 'Elixir.Logger.Supervisor' had child undefined started with 'Elixir.Logger.Watcher':watcher(error_logger, 'Elixir.Logger.ErrorHandler', {true,false,500}, link) at <0.223.0> exit with reason normal in context child_terminated
2016-09-28 20:48:30.300 [error] <0.218.0> Supervisor 'Elixir.Logger.Supervisor' had child undefined started with 'Elixir.Logger.Watcher':watcher(error_logger, 'Elixir.Logger.ErrorHandler', {true,false,500}, link) at <0.223.0> exit with reason normal in context child_terminated
2016-09-28 20:48:37.143 [error] <0.218.0> Supervisor 'Elixir.Logger.Supervisor' had child undefined started with 'Elixir.Logger.Watcher':watcher(error_logger, 'Elixir.Logger.ErrorHandler', {true,false,500}, link) at <0.223.0> exit with reason normal in context child_terminated
2016-09-28 20:48:48.388 [error] <0.218.0> Supervisor 'Elixir.Logger.Supervisor' had child undefined started with 'Elixir.Logger.Watcher':watcher(error_logger, 'Elixir.Logger.ErrorHandler', {true,false,500}, link) at <0.223.0> exit with reason normal in context child_terminated
2016-09-28 20:49:01.391 [error] <0.218.0> Supervisor 'Elixir.Logger.Supervisor' had child undefined started with 'Elixir.Logger.Watcher':watcher(error_logger, 'Elixir.Logger.ErrorHandler', {true,false,500}, link) at <0.223.0> exit with reason normal in context child_terminated
2016-09-28 20:50:26.254 [error] <0.241.0> Supervisor 'Elixir.Logger.Supervisor' had child undefined started with 'Elixir.Logger.Watcher':watcher(error_logger, 'Elixir.Logger.ErrorHandler', {true,false,500}, link) at <0.246.0> exit with reason normal in context child_terminated
2016-09-28 20:50:34.894 [error] <0.241.0> Supervisor 'Elixir.Logger.Supervisor' had child undefined started with 'Elixir.Logger.Watcher':watcher(error_logger, 'Elixir.Logger.ErrorHandler', {true,false,500}, link) at <0.246.0> exit with reason normal in context child_terminated
2016-09-28 20:50:52.162 [error] <0.218.0> Supervisor 'Elixir.Logger.Supervisor' had child undefined started with 'Elixir.Logger.Watcher':watcher(error_logger, 'Elixir.Logger.ErrorHandler', {true,false,500}, link) at <0.223.0> exit with reason normal in context child_terminated
2016-09-28 20:52:31.893 [error] <0.218.0> Supervisor 'Elixir.Logger.Supervisor' had child undefined started with 'Elixir.Logger.Watcher':watcher(error_logger, 'Elixir.Logger.ErrorHandler', {true,false,500}, link) at <0.223.0> exit with reason normal in context child_terminated
2016-09-28 20:56:44.774 [error] <0.218.0> Supervisor 'Elixir.Logger.Supervisor' had child undefined started with 'Elixir.Logger.Watcher':watcher(error_logger, 'Elixir.Logger.ErrorHandler', {true,false,500}, link) at <0.223.0> exit with reason normal in context child_terminated
2016-09-28 20:58:10.059 [error] <0.218.0> Supervisor 'Elixir.Logger.Supervisor' had child undefined started with 'Elixir.Logger.Watcher':watcher(error_logger, 'Elixir.Logger.ErrorHandler', {true,false,500}, link) at <0.223.0> exit with reason normal in context child_terminated
2016-09-28 20:58:10.786 [error] <0.5361.0> gen_server <0.5361.0> terminated with reason: no function clause matching 'Elixir.Perf.ApiChannel':handle_in(<<"get:session">>, #{<<"token">> => <<"eyJhbGciOiJIUzUxMiIsInR5cCI6IkpXVCJ9.eyJhdWQiOiJVc2VyOjMwODciLCJleHAiOjE0Nzc3...">>}, #{'__struct__' => 'Elixir.Phoenix.Socket',assigns => #{},channel => 'Elixir.Perf.ApiChannel',channel_pid => ...,...}) line 64
2016-09-28 20:58:10.786 [error] <0.5361.0> CRASH REPORT Process <0.5361.0> with 1 neighbours exited with reason: no function clause matching 'Elixir.Perf.ApiChannel':handle_in(<<"get:session">>, #{<<"token">> => <<"eyJhbGciOiJIUzUxMiIsInR5cCI6IkpXVCJ9.eyJhdWQiOiJVc2VyOjMwODciLCJleHAiOjE0Nzc3...">>}, #{'__struct__' => 'Elixir.Phoenix.Socket',assigns => #{},channel => 'Elixir.Perf.ApiChannel',channel_pid => ...,...}) line 64 in gen_server:terminate/7 line 826
2016-09-28 20:58:10.797 [error] <0.5364.0> gen_server <0.5364.0> terminated with reason: no function clause matching 'Elixir.Perf.ApiChannel':handle_in(<<"get:session">>, #{<<"token">> => <<"eyJhbGciOiJIUzUxMiIsInR5cCI6IkpXVCJ9.eyJhdWQiOiJVc2VyOjMwODgiLCJleHAiOjE0Nzc3...">>}, #{'__struct__' => 'Elixir.Phoenix.Socket',assigns => #{},channel => 'Elixir.Perf.ApiChannel',channel_pid => ...,...}) line 64
2016-09-28 20:59:27.207 [error] <0.241.0> Supervisor 'Elixir.Logger.Supervisor' had child undefined started with 'Elixir.Logger.Watcher':watcher(error_logger, 'Elixir.Logger.ErrorHandler', {true,false,500}, link) at <0.246.0> exit with reason normal in context child_terminated
2016-09-28 20:59:27.824 [error] <0.5384.0> gen_server <0.5384.0> terminated with reason: no function clause matching 'Elixir.Perf.ApiChannel':handle_in(<<"get:session">>, #{<<"token">> => <<"eyJhbGciOiJIUzUxMiIsInR5cCI6IkpXVCJ9.eyJhdWQiOiJVc2VyOjMwODkiLCJleHAiOjE0Nzc3...">>}, #{'__struct__' => 'Elixir.Phoenix.Socket',assigns => #{},channel => 'Elixir.Perf.ApiChannel',channel_pid => ...,...}) line 64
2016-09-28 20:59:27.825 [error] <0.5384.0> CRASH REPORT Process <0.5384.0> with 1 neighbours exited with reason: no function clause matching 'Elixir.Perf.ApiChannel':handle_in(<<"get:session">>, #{<<"token">> => <<"eyJhbGciOiJIUzUxMiIsInR5cCI6IkpXVCJ9.eyJhdWQiOiJVc2VyOjMwODkiLCJleHAiOjE0Nzc3...">>}, #{'__struct__' => 'Elixir.Phoenix.Socket',assigns => #{},channel => 'Elixir.Perf.ApiChannel',channel_pid => ...,...}) line 64 in gen_server:terminate/7 line 826
2016-09-28 20:59:27.837 [error] <0.5387.0> gen_server <0.5387.0> terminated with reason: no function clause matching 'Elixir.Perf.ApiChannel':handle_in(<<"get:session">>, #{<<"token">> => <<"eyJhbGciOiJIUzUxMiIsInR5cCI6IkpXVCJ9.eyJhdWQiOiJVc2VyOjMwOTAiLCJleHAiOjE0Nzc3...">>}, #{'__struct__' => 'Elixir.Phoenix.Socket',assigns => #{},channel => 'Elixir.Perf.ApiChannel',channel_pid => ...,...}) line 64
2016-09-28 20:59:46.059 [error] <0.218.0> Supervisor 'Elixir.Logger.Supervisor' had child undefined started with 'Elixir.Logger.Watcher':watcher(error_logger, 'Elixir.Logger.ErrorHandler', {true,false,500}, link) at <0.223.0> exit with reason normal in context child_terminated
2016-09-28 21:00:07.620 [error] <0.218.0> Supervisor 'Elixir.Logger.Supervisor' had child undefined started with 'Elixir.Logger.Watcher':watcher(error_logger, 'Elixir.Logger.ErrorHandler', {true,false,500}, link) at <0.223.0> exit with reason normal in context child_terminated
2016-09-28 21:00:08.324 [error] <0.5361.0> gen_server <0.5361.0> terminated with reason: no function clause matching 'Elixir.Perf.ApiChannel':handle_in(<<"get:session">>, #{<<"token">> => <<"eyJhbGciOiJIUzUxMiIsInR5cCI6IkpXVCJ9.eyJhdWQiOiJVc2VyOjMwOTUiLCJleHAiOjE0Nzc3...">>}, #{'__struct__' => 'Elixir.Phoenix.Socket',assigns => #{},channel => 'Elixir.Perf.ApiChannel',channel_pid => ...,...}) line 64
2016-09-28 21:00:08.324 [error] <0.5361.0> CRASH REPORT Process <0.5361.0> with 1 neighbours exited with reason: no function clause matching 'Elixir.Perf.ApiChannel':handle_in(<<"get:session">>, #{<<"token">> => <<"eyJhbGciOiJIUzUxMiIsInR5cCI6IkpXVCJ9.eyJhdWQiOiJVc2VyOjMwOTUiLCJleHAiOjE0Nzc3...">>}, #{'__struct__' => 'Elixir.Phoenix.Socket',assigns => #{},channel => 'Elixir.Perf.ApiChannel',channel_pid => ...,...}) line 64 in gen_server:terminate/7 line 826
2016-09-28 21:00:08.332 [error] <0.5364.0> gen_server <0.5364.0> terminated with reason: no function clause matching 'Elixir.Perf.ApiChannel':handle_in(<<"get:session">>, #{<<"token">> => <<"eyJhbGciOiJIUzUxMiIsInR5cCI6IkpXVCJ9.eyJhdWQiOiJVc2VyOjMwOTYiLCJleHAiOjE0Nzc3...">>}, #{'__struct__' => 'Elixir.Phoenix.Socket',assigns => #{},channel => 'Elixir.Perf.ApiChannel',channel_pid => ...,...}) line 64
2016-09-28 21:06:43.502 [error] <0.229.0> Supervisor 'Elixir.Logger.Supervisor' had child undefined started with 'Elixir.Logger.Watcher':watcher(error_logger, 'Elixir.Logger.ErrorHandler', {true,false,500}, link) at <0.234.0> exit with reason normal in context child_terminated
2016-09-28 21:06:44.144 [error] <0.5372.0> gen_server <0.5372.0> terminated with reason: #{'__exception__' => true,'__struct__' => 'Elixir.RuntimeError',message => <<"Expected `handle_in/3` to return one of:\n\n    {:noreply, Socket.t} |\n    {:reply, {status :: atom, response :: map}, Socket.t} |\n    {:reply, status :: atom, Socket.t} |\n    {:stop, reason :: term, Socket.t} |\n    {:stop, reason :: term, {status :: atom, response :: map}, Socket.t} |\n    {:stop, reason :: term, status :: atom, Socket.t}\n\ngot %Perf.Resource.State{conn: nil, error: %{english: \"get:session action is no...">>} in 'Elixir.Phoenix.Channel.Server':handle_result/2 line 304
2016-09-28 21:06:44.145 [error] <0.5372.0> CRASH REPORT Process <0.5372.0> with 1 neighbours exited with reason: #{'__exception__' => true,'__struct__' => 'Elixir.RuntimeError',message => <<"Expected `handle_in/3` to return one of:\n\n    {:noreply, Socket.t} |\n    {:reply, {status :: atom, response :: map}, Socket.t} |\n    {:reply, status :: atom, Socket.t} |\n    {:stop, reason :: term, Socket.t} |\n    {:stop, reason :: term, {status :: atom, response :: map}, Socket.t} |\n    {:stop, reason :: term, status :: atom, Socket.t}\n\ngot %Perf.Resource.State{conn: nil, error: %{english: \"get:session action is no...">>} in 'Elixir.Phoenix.Channel.Server':handle_result/2 line 304 in gen_server:terminate/7 line 826
2016-09-28 21:06:44.147 [error] <0.5375.0> gen_server <0.5375.0> terminated with reason: #{'__exception__' => true,'__struct__' => 'Elixir.RuntimeError',message => <<"Expected `handle_in/3` to return one of:\n\n    {:noreply, Socket.t} |\n    {:reply, {status :: atom, response :: map}, Socket.t} |\n    {:reply, status :: atom, Socket.t} |\n    {:stop, reason :: term, Socket.t} |\n    {:stop, reason :: term, {status :: atom, response :: map}, Socket.t} |\n    {:stop, reason :: term, status :: atom, Socket.t}\n\ngot %Perf.Resource.State{conn: nil, error: %{english: \"get:session action is no...">>} in 'Elixir.Phoenix.Channel.Server':handle_result/2 line 304
2016-09-28 21:06:55.974 [error] <0.229.0> Supervisor 'Elixir.Logger.Supervisor' had child undefined started with 'Elixir.Logger.Watcher':watcher(error_logger, 'Elixir.Logger.ErrorHandler', {true,false,500}, link) at <0.234.0> exit with reason normal in context child_terminated
2016-09-28 21:09:18.507 [error] <0.229.0> Supervisor 'Elixir.Logger.Supervisor' had child undefined started with 'Elixir.Logger.Watcher':watcher(error_logger, 'Elixir.Logger.ErrorHandler', {true,false,500}, link) at <0.234.0> exit with reason normal in context child_terminated
2016-09-28 21:09:34.365 [error] <0.218.0> Supervisor 'Elixir.Logger.Supervisor' had child undefined started with 'Elixir.Logger.Watcher':watcher(error_logger, 'Elixir.Logger.ErrorHandler', {true,false,500}, link) at <0.223.0> exit with reason normal in context child_terminated
2016-09-28 21:10:32.053 [error] <0.218.0> Supervisor 'Elixir.Logger.Supervisor' had child undefined started with 'Elixir.Logger.Watcher':watcher(error_logger, 'Elixir.Logger.ErrorHandler', {true,false,500}, link) at <0.223.0> exit with reason normal in context child_terminated
2016-09-28 21:11:11.747 [error] <0.657.0> Supervisor 'Elixir.Logger.Supervisor' had child undefined started with 'Elixir.Logger.Watcher':watcher(error_logger, 'Elixir.Logger.ErrorHandler', {true,false,500}, link) at <0.662.0> exit with reason normal in context child_terminated
2016-09-28 21:11:18.813 [error] <0.5919.0> gen_server <0.5919.0> terminated with reason: bad arithmetic expression in 'Elixir.Poison.Encoder.Perf.Run':'-encode/2-fun-0-'/2 line 93
2016-09-28 21:11:18.814 [error] <0.5919.0> CRASH REPORT Process <0.5919.0> with 0 neighbours exited with reason: bad arithmetic expression in 'Elixir.Poison.Encoder.Perf.Run':'-encode/2-fun-0-'/2 line 93 in gen_server:terminate/7 line 826
2016-09-28 21:11:18.904 [error] <0.5934.0> gen_server <0.5934.0> terminated with reason: #{'__exception__' => true,'__struct__' => 'Elixir.ArgumentError',message => <<"ranges (first..last) expect both sides to be integers, got: 0..nil">>} in 'Elixir.Range':new/2 line 55
2016-09-28 21:11:18.905 [error] <0.5934.0> CRASH REPORT Process <0.5934.0> with 0 neighbours exited with reason: #{'__exception__' => true,'__struct__' => 'Elixir.ArgumentError',message => <<"ranges (first..last) expect both sides to be integers, got: 0..nil">>} in 'Elixir.Range':new/2 line 55 in gen_server:terminate/7 line 826
